WARNING : Project's CLI version could not be detected from `requirements.txt`.
WARNING : Try `pretext init --refresh` to produce a compatible file.
INFO    : Found entry no longer exists 4347
INFO    : Now preparing local server to preview your project directory `/workspaces/MathForElementarySchoolTeachers`.
INFO    :   (Reminder: use `pretext deploy` to deploy your built project to a public
INFO    :   GitHub Pages site that can be shared with readers who cannot access your
INFO    :   personal computer.)
INFO    : 
INFO    : starting server ...
INFO    : Running in a codespace, so using a subprocess server.
INFO    : Starting the server
INFO    : There are 10 or more servers on file. Cleaning up ...
INFO    : Found entry no longer exists 4347
INFO    : Terminating 4347
INFO    : Terminate failed for 4347.
ERROR   : process PID not found (pid=4347)
Traceback (most recent call last):
  File "/usr/local/python/3.12.1/lib/python3.12/site-packages/pretext/server.py", line 76, in terminate
    psutil.Process(self.pid).terminate()
    ^^^^^^^^^^^^^^^^^^^^^^^^
  File "/home/codespace/.local/lib/python3.12/site-packages/psutil/__init__.py", line 317, in __init__
    self._init(pid)
  File "/home/codespace/.local/lib/python3.12/site-packages/psutil/__init__.py", line 363, in _init
    raise NoSuchProcess(pid, msg=msg) from None
psutil.NoSuchProcess: process PID not found (pid=4347)
INFO    : Found entry no longer exists 4062
INFO    : Terminating 4062
INFO    : Terminate failed for 4062.
ERROR   : process PID not found (pid=4062)
Traceback (most recent call last):
  File "/usr/local/python/3.12.1/lib/python3.12/site-packages/pretext/server.py", line 76, in terminate
    psutil.Process(self.pid).terminate()
    ^^^^^^^^^^^^^^^^^^^^^^^^
  File "/home/codespace/.local/lib/python3.12/site-packages/psutil/__init__.py", line 317, in __init__
    self._init(pid)
  File "/home/codespace/.local/lib/python3.12/site-packages/psutil/__init__.py", line 363, in _init
    raise NoSuchProcess(pid, msg=msg) from None
psutil.NoSuchProcess: process PID not found (pid=4062)
INFO    : Found entry no longer exists 2632
INFO    : Terminating 2632
INFO    : Terminate failed for 2632.
ERROR   : process PID not found (pid=2632)
Traceback (most recent call last):
  File "/usr/local/python/3.12.1/lib/python3.12/site-packages/pretext/server.py", line 76, in terminate
    psutil.Process(self.pid).terminate()
    ^^^^^^^^^^^^^^^^^^^^^^^^
  File "/home/codespace/.local/lib/python3.12/site-packages/psutil/__init__.py", line 317, in __init__
    self._init(pid)
  File "/home/codespace/.local/lib/python3.12/site-packages/psutil/__init__.py", line 363, in _init
    raise NoSuchProcess(pid, msg=msg) from None
psutil.NoSuchProcess: process PID not found (pid=2632)
INFO    : Found entry no longer exists 4739
INFO    : Terminating 4739
INFO    : Terminate failed for 4739.
ERROR   : process PID not found (pid=4739)
Traceback (most recent call last):
  File "/usr/local/python/3.12.1/lib/python3.12/site-packages/pretext/server.py", line 76, in terminate
    psutil.Process(self.pid).terminate()
    ^^^^^^^^^^^^^^^^^^^^^^^^
  File "/home/codespace/.local/lib/python3.12/site-packages/psutil/__init__.py", line 317, in __init__
    self._init(pid)
  File "/home/codespace/.local/lib/python3.12/site-packages/psutil/__init__.py", line 363, in _init
    raise NoSuchProcess(pid, msg=msg) from None
psutil.NoSuchProcess: process PID not found (pid=4739)
INFO    : Found entry no longer exists 8971
INFO    : Terminating 8971
INFO    : Terminate failed for 8971.
ERROR   : process PID not found (pid=8971)
Traceback (most recent call last):
  File "/usr/local/python/3.12.1/lib/python3.12/site-packages/pretext/server.py", line 76, in terminate
    psutil.Process(self.pid).terminate()
    ^^^^^^^^^^^^^^^^^^^^^^^^
  File "/home/codespace/.local/lib/python3.12/site-packages/psutil/__init__.py", line 317, in __init__
    self._init(pid)
  File "/home/codespace/.local/lib/python3.12/site-packages/psutil/__init__.py", line 363, in _init
    raise NoSuchProcess(pid, msg=msg) from None
psutil.NoSuchProcess: process PID not found (pid=8971)
INFO    : Found entry no longer exists 2309
INFO    : Terminating 2309
INFO    : Terminate failed for 2309.
ERROR   : process PID not found (pid=2309)
Traceback (most recent call last):
  File "/usr/local/python/3.12.1/lib/python3.12/site-packages/pretext/server.py", line 76, in terminate
    psutil.Process(self.pid).terminate()
    ^^^^^^^^^^^^^^^^^^^^^^^^
  File "/home/codespace/.local/lib/python3.12/site-packages/psutil/__init__.py", line 317, in __init__
    self._init(pid)
  File "/home/codespace/.local/lib/python3.12/site-packages/psutil/__init__.py", line 363, in _init
    raise NoSuchProcess(pid, msg=msg) from None
psutil.NoSuchProcess: process PID not found (pid=2309)
INFO    : Found entry no longer exists 5106
INFO    : Terminating 5106
INFO    : Terminate failed for 5106.
ERROR   : process PID not found (pid=5106)
Traceback (most recent call last):
  File "/usr/local/python/3.12.1/lib/python3.12/site-packages/pretext/server.py", line 76, in terminate
    psutil.Process(self.pid).terminate()
    ^^^^^^^^^^^^^^^^^^^^^^^^
  File "/home/codespace/.local/lib/python3.12/site-packages/psutil/__init__.py", line 317, in __init__
    self._init(pid)
  File "/home/codespace/.local/lib/python3.12/site-packages/psutil/__init__.py", line 363, in _init
    raise NoSuchProcess(pid, msg=msg) from None
psutil.NoSuchProcess: process PID not found (pid=5106)
INFO    : Found entry no longer exists 10399
INFO    : Terminating 10399
INFO    : Terminate failed for 10399.
ERROR   : process PID not found (pid=10399)
Traceback (most recent call last):
  File "/usr/local/python/3.12.1/lib/python3.12/site-packages/pretext/server.py", line 76, in terminate
    psutil.Process(self.pid).terminate()
    ^^^^^^^^^^^^^^^^^^^^^^^^
  File "/home/codespace/.local/lib/python3.12/site-packages/psutil/__init__.py", line 317, in __init__
    self._init(pid)
  File "/home/codespace/.local/lib/python3.12/site-packages/psutil/__init__.py", line 363, in _init
    raise NoSuchProcess(pid, msg=msg) from None
psutil.NoSuchProcess: process PID not found (pid=10399)
INFO    : Found entry no longer exists 8093
INFO    : Terminating 8093
INFO    : Terminate failed for 8093.
ERROR   : process PID not found (pid=8093)
Traceback (most recent call last):
  File "/usr/local/python/3.12.1/lib/python3.12/site-packages/pretext/server.py", line 76, in terminate
    psutil.Process(self.pid).terminate()
    ^^^^^^^^^^^^^^^^^^^^^^^^
  File "/home/codespace/.local/lib/python3.12/site-packages/psutil/__init__.py", line 317, in __init__
    self._init(pid)
  File "/home/codespace/.local/lib/python3.12/site-packages/psutil/__init__.py", line 363, in _init
    raise NoSuchProcess(pid, msg=msg) from None
psutil.NoSuchProcess: process PID not found (pid=8093)
INFO    : Found process 4324 no longer listening on specified port 8128
INFO    : Terminating 4324
INFO    : Added server entry f4b0ef1c60 4324 8128 localhost

INFO    : Server will soon be available at https://fuzzy-trout-pjp7wjrp96w3969j-8128.app.github.dev
INFO    : Opening browser for target `html` at https://fuzzy-trout-pjp7wjrp96w3969j-8128.app.github.dev/output/html
INFO    : 
----------------------------------------------------
INFO    : While running pretext, the following errors occurred:

INFO    : (see log messages above or in the 'logs' folder for more information)
INFO    : ----------------------------------------------------
